{
 "cells": [
  {
   "cell_type": "code",
   "execution_count": null,
   "id": "b13c2656-4d4a-4223-93fb-cad81fb82575",
   "metadata": {},
   "outputs": [],
   "source": [
    "'''In Python, an Exception is an event that occurs during the execution of a program,\n",
    "which disrupts the normal flow of the program’s instructions. When these exceptions occur,\n",
    "the Python interpreter stops the current process and passes it to the calling process until it\n",
    "is handled. If not handled, the program will crash.\n",
    "\n",
    "Examples of exceptions in Python include TypeError, ValueError, IndexError, FileNotFoundError and many more.\n",
    "These are often caused by logical errors in your code.\n",
    "\n",
    "Syntax Error is a type of error that occurs while parsing your code. This error is raised when the parser encounters\n",
    "a syntax error. This may be caused by unclosed quotes, missing parentheses, incorrect indentation, or other deviations\n",
    "from correct Python syntax.\n",
    "'''\n",
    "\n",
    "print(\"Hello World\"  # Missing closing parenthesis\n",
    "\n",
    "print(10 / 0)  # Division by zero\n",
    "\n",
    "'''\n",
    "This will result in a ZeroDivisionError (which is a type of Exception) because you can’t divide by zero.\n",
    "while syntax errors are detected before the execution of the program, exceptions are detected during the \n",
    "execution of the program. Syntax errors need to be corrected for the program to run at all, while exceptions \n",
    "can be handled at runtime using try and except blocks to prevent the program from crashing.\n",
    "'''\n"
   ]
  },
  {
   "cell_type": "code",
   "execution_count": null,
   "id": "458d8d74-2e27-4a78-a4f2-0aa5a655a4b0",
   "metadata": {},
   "outputs": [],
   "source": [
    "'''\n",
    "When an exception is not handled in Python, it causes the program to stop running and displays an error message. \n",
    "This is known as an unhandled exception. The error message includes details about the type of exception and where it occurred.\n",
    "'''\n",
    "def divide_numbers(x, y):\n",
    "    return x / y\n",
    "\n",
    "print(divide_numbers(10, 0))\n",
    "\n",
    "'''\n",
    "In this code, we’re trying to divide a number by zero, which is not allowed in mathematics. This will raise\n",
    "a ZeroDivisionError exception. If you run this code without handling the exception, the Python interpreter \n",
    "will stop at the line that caused the error and print an error message\n",
    "'''\n"
   ]
  },
  {
   "cell_type": "code",
   "execution_count": null,
   "id": "1676a5ff-4ab8-4686-abfa-f8edc5434bf5",
   "metadata": {},
   "outputs": [],
   "source": [
    "'''\n",
    "In Python, the `try`, `except`, `finally` and `raise` statements are used to catch and handle exceptions.\n",
    "\n",
    "Here's how they work:\n",
    "\n",
    "- `try`: This block contains the code that might raise an exception.\n",
    "- `except`: This block contains the code that will execute if a specific exception or any exception occurs in the try block.\n",
    "- `finally`: This block contains the code that will always execute regardless of whether an exception occurred in the try block or not.\n",
    "- `raise`: This statement allows the programmer to force a specific exception to occur.\n",
    "\n",
    "Here's an example:\n",
    "'''\n",
    "\n",
    "try:\n",
    "    # Try block\n",
    "    x = 10 / 0  # This will raise a ZeroDivisionError\n",
    "except ZeroDivisionError as e:\n",
    "    # Except block\n",
    "    print(\"Handled ZeroDivisionError:\", e)\n",
    "finally:\n",
    "    # Finally block\n",
    "    print(\"This will always execute.\")\n",
    "'''\n",
    "In this code, the division by zero in the try block raises a `ZeroDivisionError`. The except block catches this exception \n",
    "and prints a message. Then, the finally block executes and prints another message. If there were more code after this, \n",
    "execution would continue from there. If no exception occurred in the try block, the except block would be skipped, but \n",
    "the finally block would still execute.\n",
    "'''"
   ]
  },
  {
   "cell_type": "code",
   "execution_count": null,
   "id": "9057af75-5416-40bb-bc8f-718bb3c83538",
   "metadata": {},
   "outputs": [],
   "source": [
    "'''Sure, here are examples for each:\n",
    "\n",
    "1. **try and else**:\n",
    "\n",
    "The `else` clause in a `try`/`except` statement is optional and is designed to execute code that must be executed if \n",
    "the `try` block doesn't raise an exception.\n",
    "\n",
    "'''\n",
    "\n",
    "try:\n",
    "    x = 10 / 2  # This will not raise an exception\n",
    "except ZeroDivisionError:\n",
    "    print(\"You can't divide by zero!\")\n",
    "else:\n",
    "    print(\"The division was successful.\")\n",
    "\n",
    "'''    \n",
    "In this example, since the division is successful and doesn't raise an exception, the `else` block is executed.\n",
    "\n",
    "2. **finally**:\n",
    "The `finally` block is a place to put any code that must execute, whether an exception was raised or not.\n",
    "\n",
    "'''\n",
    "\n",
    "\n",
    "try:\n",
    "    x = 10 / 0  # This will raise a ZeroDivisionError\n",
    "except ZeroDivisionError:\n",
    "    print(\"You can't divide by zero!\")\n",
    "finally:\n",
    "    print(\"This will always execute.\")\n",
    "'''\n",
    "In this example, even though a `ZeroDivisionError` is raised, the `finally` block still executes.\n",
    "\n",
    "3. **raise**:\n",
    "The `raise` statement allows the programmer to force a specific exception to occur.\n",
    "\n",
    "'''\n",
    "try:\n",
    "    raise ValueError(\"This is a manually raised exception.\")\n",
    "except ValueError as e:\n",
    "    print(\"Caught an exception:\", e)\n",
    "'''\n",
    "\n",
    "In this example, we're manually raising a `ValueError` with a custom error message. The `except` block catches this exception\n",
    "and prints the message.\n",
    "'''"
   ]
  },
  {
   "cell_type": "code",
   "execution_count": null,
   "id": "a56f7bb9-ad08-4f81-b739-9b0746bc7f01",
   "metadata": {},
   "outputs": [],
   "source": [
    "'''\n",
    "Sure, here's an example of how you can create a custom exception class in Python:\n",
    "\n",
    "'''\n",
    "# Define the custom exception class\n",
    "class CustomError(Exception):\n",
    "    def __init__(self, message):\n",
    "        self.message = message\n",
    "    def __str__(self):\n",
    "        return self.message\n",
    "\n",
    "# Use the custom exception class\n",
    "try:\n",
    "    raise CustomError(\"This is a custom error.\")\n",
    "except CustomError as e:\n",
    "    print(\"Caught an exception:\", e)\n",
    "\n",
    "'''\n",
    "In this code, we first define a `CustomError` class that inherits from the built-in `Exception` class. \n",
    "We override the `__init__` method to accept a custom error message, and the `__str__` method to return \n",
    "this message when the exception is printed.\n",
    "\n",
    "Then, in the `try` block, we raise our custom exception using the `raise` keyword. The `except` block \n",
    "catches this exception and prints the message.\n",
    "'''"
   ]
  }
 ],
 "metadata": {
  "kernelspec": {
   "display_name": "Python 3 (ipykernel)",
   "language": "python",
   "name": "python3"
  },
  "language_info": {
   "codemirror_mode": {
    "name": "ipython",
    "version": 3
   },
   "file_extension": ".py",
   "mimetype": "text/x-python",
   "name": "python",
   "nbconvert_exporter": "python",
   "pygments_lexer": "ipython3",
   "version": "3.10.8"
  }
 },
 "nbformat": 4,
 "nbformat_minor": 5
}
